<?xml version="1.0" ?>
<!-- =================================================================================== -->
<!-- |    This document was autogenerated by xacro from swarm_bot.urdf.xacro           | -->
<!-- |    EDITING THIS FILE BY HAND IS NOT RECOMMENDED                                 | -->
<!-- =================================================================================== -->
<robot name="swarm_bot">
  <!-- Specify some standard inertial calculations https://en.wikipedia.org/wiki/List_of_moments_of_inertia -->
  <!-- These make use of xacro's mathematical functionality -->
  <gazebo>
    <!-- <plugin name='diff_drive' filename='libgazebo_ros_diff_drive.so'> -->
    <plugin filename="libgazebo_ros_diff_drive.so" name="diff_drive_controller">
      <!-- ROS parameters -->
      <ros>
        <namespace>robot_namespace</namespace>
        <param name="robot_description" value="robot_description"/>
      </ros>
      <!-- Wheel Information -->
      <left_joint>left_wheel_joint</left_joint>
      <right_joint>right_wheel_joint</right_joint>
      <wheel_separation>0.105</wheel_separation>
      <wheel_diameter>0.065</wheel_diameter>
      <!-- Limits -->
      <max_wheel_torque>200</max_wheel_torque>
      <max_wheel_acceleration>10.0</max_wheel_acceleration>
      <!-- Output -->
      <odometry_frame>odom</odometry_frame>
      <robot_base_frame>origin_link</robot_base_frame>
      <publish_odom>true</publish_odom>
      <publish_odom_tf>true</publish_odom_tf>
      <publish_wheel_tf>true</publish_wheel_tf>
    </plugin>
  </gazebo>
  <link name="laser_frame">
    <visual>
      <geometry>
        <cylinder length="0.045" radius="0.0325"/>
      </geometry>
      <material name="orange">
        <color rgba="1 0.3 0.1 1"/>
      </material>
    </visual>
    <collision>
      <geometry>
        <cylinder length="0.045" radius="0.0325"/>
      </geometry>
    </collision>
    <inertial>
      <origin rpy="0 0 0" xyz="0 0 0"/>
      <mass value="0.1"/>
      <inertia ixx="4.3281250000000005e-05" ixy="0.0" ixz="0.0" iyy="4.3281250000000005e-05" iyz="0.0" izz="5.281250000000001e-05"/>
    </inertial>
  </link>
  <joint name="laser_joint" type="fixed">
    <parent link="base_link"/>
    <child link="laser_frame"/>
    <origin rpy="0 0 0" xyz="0 0 0.205"/>
  </joint>
  <gazebo reference="laser_frame">
    <material>Gazebo/Orange</material>
    <sensor name="laser" type="ray">
      <pose> 0 0 0 0 0 0 </pose>
      <always_on>true</always_on>
      <visualize>true</visualize>
      <update_rate>10</update_rate>
      <ray>
        <scan>
          <horizontal>
            <samples>360</samples>
            <min_angle>-3.14</min_angle>
            <max_angle>3.14</max_angle>
          </horizontal>
        </scan>
        <range>
          <min>0.2</min>
          <max>12</max>
        </range>
      </ray>
      <plugin filename="libgazebo_ros_ray_sensor.so" name="laser_controller">
        <ros>
          <argument>~/out:=scan</argument>
        </ros>
        <output_type>sensor_msgs/LaserScan</output_type>
        <!-- <topicName>/scan</topicName> -->
        <frame_name>laser_frame</frame_name>
      </plugin>
    </sensor>
  </gazebo>
  <!-- LINKS -->
  <!-- Origin -->
  <link name="origin_link">
    </link>
  <!-- Base -->
  <link name="base_link">
    <visual>
      <!-- change the position of the visualization only, not the axis -->
      <origin rpy="0 0 0" xyz="0 0 0.1075"/>
      <geometry>
        <!-- unit/ meter -->
        <cylinder length="0.15" radius="0.107"/>
      </geometry>
      <material name="white">
        <color rgba="1 1 1 1"/>
      </material>
    </visual>
    <collision>
      <origin rpy="0 0 0" xyz="0 0 0.1075"/>
      <geometry>
        <cylinder length="0.15" radius="0.107"/>
      </geometry>
    </collision>
    <inertial>
      <origin rpy="0 0 0" xyz="0 0 0.1075"/>
      <mass value="0.5"/>
      <inertia ixx="0.002368625" ixy="0.0" ixz="0.0" iyy="0.002368625" iyz="0.0" izz="0.0028622499999999998"/>
    </inertial>
  </link>
  <gazebo reference="base_link">
    <material>Gazebo/White</material>
  </gazebo>
  <!-- Left Wheel -->
  <link name="right_wheel">
    <visual>
      <geometry>
        <cylinder length="0.03" radius="0.0325"/>
      </geometry>
      <material name="black">
        <color rgba="0.0 0.0 0.0 1.0"/>
      </material>
    </visual>
    <collision>
      <geometry>
        <cylinder length="0.03" radius="0.0325"/>
      </geometry>
    </collision>
    <inertial>
      <origin rpy="0 0 0" xyz="0 0 0"/>
      <mass value="0.2"/>
      <inertia ixx="6.78125e-05" ixy="0.0" ixz="0.0" iyy="6.78125e-05" iyz="0.0" izz="0.00010562500000000002"/>
    </inertial>
  </link>
  <gazebo reference="right_wheel">
    <material>Gazebo/Black</material>
  </gazebo>
  <!-- Right Wheel -->
  <link name="left_wheel">
    <visual>
      <geometry>
        <cylinder length="0.03" radius="0.0325"/>
      </geometry>
      <material name="black">
        <color rgba="0.0 0.0 0.0 1.0"/>
      </material>
    </visual>
    <collision>
      <geometry>
        <cylinder length="0.03" radius="0.0325"/>
      </geometry>
    </collision>
    <inertial>
      <origin rpy="0 0 0" xyz="0 0 0"/>
      <mass value="0.2"/>
      <inertia ixx="6.78125e-05" ixy="0.0" ixz="0.0" iyy="6.78125e-05" iyz="0.0" izz="0.00010562500000000002"/>
    </inertial>
  </link>
  <gazebo reference="left_wheel">
    <material>Gazebo/Black</material>
  </gazebo>
  <!-- Front Passive Wheel -->
  <link name="front_passive_wheel">
    <visual>
      <geometry>
        <sphere radius="0.024"/>
      </geometry>
      <material name="black">
        <color rgba="0.0 0.0 0.0 1.0"/>
      </material>
    </visual>
    <collision>
      <geometry>
        <sphere radius="0.024"/>
      </geometry>
    </collision>
    <inertial>
      <origin rpy="0 0 0" xyz="0 0 0"/>
      <mass value="0.1"/>
      <inertia ixx="0.00010000000000000005" ixy="0.0" ixz="0.0" iyy="0.00010000000000000005" iyz="0.0" izz="0.00010000000000000005"/>
    </inertial>
  </link>
  <gazebo reference="front_passive_wheel">
    <material>Gazebo/Black</material>
    <!-- reduce friction to make the wheels able to roll -->
    <mu1 value="0.001"/>
    <mu2 value="0.001"/>
  </gazebo>
  <!-- Back Passive Wheel -->
  <link name="back_passive_wheel">
    <visual>
      <geometry>
        <sphere radius="0.024"/>
      </geometry>
      <material name="black">
        <color rgba="0.0 0.0 0.0 1.0"/>
      </material>
    </visual>
    <collision>
      <geometry>
        <sphere radius="0.024"/>
      </geometry>
    </collision>
    <inertial>
      <origin rpy="0 0 0" xyz="0 0 0"/>
      <mass value="0.1"/>
      <inertia ixx="2.3040000000000006e-05" ixy="0.0" ixz="0.0" iyy="2.3040000000000006e-05" iyz="0.0" izz="2.3040000000000006e-05"/>
    </inertial>
  </link>
  <gazebo reference="back_passive_wheel">
    <material>Gazebo/Black</material>
    <mu1 value="0.001"/>
    <mu2 value="0.001"/>
  </gazebo>
  <!-- JOINTS-->
  <!-- Base -->
  <joint name="origin_joint" type="fixed">
    <parent link="origin_link"/>
    <child link="base_link"/>
    <origin xyz="0 0 -0.0325"/>
  </joint>
  <!-- Left Wheel -->
  <joint name="right_wheel_joint" type="continuous">
    <parent link="origin_link"/>
    <child link="right_wheel"/>
    <!-- rotate wheel 90 deg around x-axis -->
    <origin rpy="-1.5707963267948966 0 0" xyz="0 -0.107 0"/>
    <axis xyz="0 0 1"/>
  </joint>
  <!-- Right Wheel -->
  <joint name="left_wheel_joint" type="continuous">
    <parent link="origin_link"/>
    <child link="left_wheel"/>
    <origin rpy="1.5707963267948966 0 0" xyz="0 0.107 0"/>
    <axis xyz="0 0 -1"/>
  </joint>
  <!-- Front Passive Wheel -->
  <joint name="front_passive_wheel_joint" type="fixed">
    <parent link="origin_link"/>
    <child link="front_passive_wheel"/>
    <origin rpy="0 0 0" xyz="0.067 0 -0.0085"/>
  </joint>
  <!-- Back Passive Wheel -->
  <joint name="back_passive_wheel_joint" type="fixed">
    <parent link="origin_link"/>
    <child link="back_passive_wheel"/>
    <origin rpy="0 0 0" xyz="-0.067 0 -0.0083"/>
  </joint>
</robot>
