<?xml version="1.0" ?>
<!-- =================================================================================== -->
<!-- |    This document was autogenerated by xacro from swarm_bot.urdf.xacro           | -->
<!-- |    EDITING THIS FILE BY HAND IS NOT RECOMMENDED                                 | -->
<!-- =================================================================================== -->
<robot name="swarm_bot">
  <!-- Specify some standard inertial calculations https://en.wikipedia.org/wiki/List_of_moments_of_inertia -->
  <!-- These make use of xacro's mathematical functionality -->
  <!-- Base -->
  <link name="base_link">
    <visual>
      <!-- change the position of the visualization only, not the axis -->
      <origin rpy="0 0 0" xyz="0 0 0.1075"/>
      <geometry>
        <!-- unit: meter -->
        <cylinder length="0.15" radius="0.107"/>
      </geometry>
      <material name="white">
        <color rgba="1 1 1 1"/>
      </material>
    </visual>
    <collision>
      <origin rpy="0 0 0" xyz="0 0 0.1075"/>
      <geometry>
        <cylinder length="0.15" radius="0.107"/>
      </geometry>
    </collision>
    <inertial>
      <origin rpy="0 0 0" xyz="0 0 0.1075"/>
      <mass value="0.5"/>
      <inertia ixx="0.002368625" ixy="0.0" ixz="0.0" iyy="0.002368625" iyz="0.0" izz="0.0028622499999999998"/>
    </inertial>
  </link>
  <!-- Left Wheel -->
  <link name="left_wheel">
    <visual>
      <geometry>
        <cylinder length="0.03" radius="0.0325"/>
      </geometry>
      <material name="black">
        <color rgba="0.0 0.0 0.0 1.0"/>
      </material>
    </visual>
    <collision>
      <geometry>
        <cylinder length="0.03" radius="0.0325"/>
      </geometry>
    </collision>
    <inertial>
      <origin rpy="0 0 0" xyz="0 0 0"/>
      <mass value="0.2"/>
      <inertia ixx="6.78125e-05" ixy="0.0" ixz="0.0" iyy="6.78125e-05" iyz="0.0" izz="0.00010562500000000002"/>
    </inertial>
  </link>
  <!-- Right Wheel -->
  <link name="right_wheel">
    <visual>
      <geometry>
        <cylinder length="0.03" radius="0.0325"/>
      </geometry>
      <material name="black">
        <color rgba="0.0 0.0 0.0 1.0"/>
      </material>
    </visual>
    <collision>
      <geometry>
        <cylinder length="0.03" radius="0.0325"/>
      </geometry>
    </collision>
    <inertial>
      <origin rpy="0 0 0" xyz="0 0 0"/>
      <mass value="0.2"/>
      <inertia ixx="6.78125e-05" ixy="0.0" ixz="0.0" iyy="6.78125e-05" iyz="0.0" izz="0.00010562500000000002"/>
    </inertial>
  </link>
  <!-- Front Passive Wheel -->
  <link name="front_passive_wheel">
    <visual>
      <geometry>
        <sphere radius="0.024"/>
      </geometry>
      <material name="black">
        <color rgba="0.0 0.0 0.0 1.0"/>
      </material>
    </visual>
    <collision>
      <geometry>
        <sphere radius="0.024"/>
      </geometry>
    </collision>
    <inertial>
      <origin rpy="0 0 0" xyz="0 0 0"/>
      <mass value="0.1"/>
      <inertia ixx="0.00010000000000000005" ixy="0.0" ixz="0.0" iyy="0.00010000000000000005" iyz="0.0" izz="0.00010000000000000005"/>
    </inertial>
  </link>
  <!-- Back Passive Wheel -->
  <link name="back_passive_wheel">
    <visual>
      <geometry>
        <sphere radius="0.024"/>
      </geometry>
      <material name="black">
        <color rgba="0.0 0.0 0.0 1.0"/>
      </material>
    </visual>
    <collision>
      <geometry>
        <sphere radius="0.024"/>
      </geometry>
    </collision>
    <inertial>
      <origin rpy="0 0 0" xyz="0 0 0"/>
      <mass value="0.1"/>
      <inertia ixx="2.3040000000000006e-05" ixy="0.0" ixz="0.0" iyy="2.3040000000000006e-05" iyz="0.0" izz="2.3040000000000006e-05"/>
    </inertial>
  </link>
  <!-- Lidar -->
  <link name="lidar">
    <visual>
      <geometry>
        <cylinder length="0.045" radius="0.0325"/>
      </geometry>
      <material name="blue">
        <color rgba="0.0 0.0 1.0 1.0"/>
      </material>
    </visual>
    <collision>
      <geometry>
        <cylinder length="0.045" radius="0.0325"/>
      </geometry>
    </collision>
    <inertial>
      <origin rpy="0 0 0" xyz="0 0 0"/>
      <mass value="0.1"/>
      <inertia ixx="4.3281250000000005e-05" ixy="0.0" ixz="0.0" iyy="4.3281250000000005e-05" iyz="0.0" izz="5.281250000000001e-05"/>
    </inertial>
  </link>
  <!-- Joints -->
  <!-- Left Wheel -->
  <joint name="left_wheel_joint" type="continuous">
    <parent link="base_link"/>
    <child link="left_wheel"/>
    <!-- rotate wheel 90 deg around x-axis -->
    <origin rpy="-1.5708 0 0" xyz="0 -0.107 0.0325"/>
    <axis xyz="0 1 0"/>
  </joint>
  <!-- Right Wheel -->
  <joint name="right_wheel_joint" type="continuous">
    <parent link="base_link"/>
    <child link="right_wheel"/>
    <origin rpy="1.5708 0 0" xyz="0 0.107 0.0325"/>
    <axis xyz="0 1 0"/>
  </joint>
  <!-- Front Passive Wheel -->
  <joint name="front_passive_wheel_joint" type="continuous">
    <parent link="base_link"/>
    <child link="front_passive_wheel"/>
    <origin rpy="0 0 0" xyz="0.067 0 0.024"/>
  </joint>
  <!-- Back Passive Wheel -->
  <joint name="back_passive_wheel_joint" type="continuous">
    <parent link="base_link"/>
    <child link="back_passive_wheel"/>
    <origin rpy="0 0 0" xyz="-0.067 0 0.022"/>
  </joint>
  <!-- Lidar -->
  <joint name="lidar_joint" type="fixed">
    <parent link="base_link"/>
    <child link="lidar"/>
    <origin rpy="0 0 0" xyz="0 0 0.205"/>
  </joint>
</robot>
